Workbook
Name ACRES_PER_BED: Inputs!$B$6
Name CARROT_DIM_PCT: Inputs!$B$23
Name CARROT_FERTILIZER_PER_BED: Inputs!$B$22
Name CARROT_HRS_PER_BED: Inputs!$B$21
Name CARROT_MAX_BEDS: Inputs!$B$19
Name CARROT_PRICE: Inputs!$B$20
Name FARM_ACREAGE: Inputs!$B$5
Name FARMER_HRS_AVAILABLE: Inputs!$B$9
Name FARMER_LABOR_RATE: Inputs!$B$10
Name FIXED_COST: Inputs!$B$8
Name MAX_TEMP_WORKERS: Inputs!$B$13
Name MESCLUN_DIM_PCT: Inputs!$B$28
Name MESCLUN_FERTILIZER_PER_BED: Inputs!$B$27
Name MESCLUN_HRS_PER_BED: Inputs!$B$26
Name MESCLUN_MAX_BEDS: Inputs!$B$24
Name MESCLUN_PRICE: Inputs!$B$25
Name SEASON_WEEKS: Inputs!$B$4
Name TEMP_HRS_PER_WORKER: Inputs!$B$11
Name TEMP_LABOR_RATE: Inputs!$B$12
Name TOMATO_DIM_PCT: Inputs!$B$18
Name TOMATO_FERTILIZER_PER_BED: Inputs!$B$17
Name TOMATO_HRS_PER_BED: Inputs!$B$16
Name TOMATO_MAX_BEDS: Inputs!$B$14
Name TOMATO_PRICE: Inputs!$B$15
Name TOTAL_BED_CAPACITY: Inputs!$B$7

Sheet Inputs
A1: Perfect Competition — Model Inputs
A3: Name | B3: Value | C3: Unit | D3: Source | E3: Contract name
A4: Season weeks | B4: 36 | C4: weeks | D4: Case instructions | E4: SEASON_WEEKS
A5: Farm acreage | B5: 1.5 | C5: acres | D5: Case instructions | E5: FARM_ACREAGE
A6: Acres Per Bed | B6: 0.02 | C6: acres/bed | D6: Modeling assumption | E6: ACRES_PER_BED
A7: Total Bed Capacity | B7: 64 | C7: beds | D7: Case instructions | E7: TOTAL_BED_CAPACITY
A8: Fixed cost | B8: 20000 | C8: dollars/season | D8: Case instructions | E8: FIXED_COST
A9: Farmer hours available | B9: 720 | C9: hours/season | D9: Case instructions | E9: FARMER_HRS_AVAILABLE
A10: Farmer Labor Rate | B10: =50000/1440 -> 34.722222 | C10: dollars/hour | D10: Case instructions | E10: FARMER_LABOR_RATE
A11: Temp Hours per Worker | B11: 1440 | C11: hours/worker | D11: Case instructions | E11: TEMP_HRS_PER_WORKER
A12: Temp Labor Rate | B12: =25000/1440 -> 17.361111 | C12: dollars/hour | D12: Case instructions | E12: TEMP_LABOR_RATE
A13: Max Temp Workers | B13: 4 | C13: workers | D13: Case instructions | E13: MAX_TEMP_WORKERS
A14: Tomato Max Beds | B14: 20 | C14: beds | D14: Case instructions | E14: TOMATO_MAX_BEDS
A15: Tomato Price | B15: 8800 | C15: dollars/bed | D15: Case instructions | E15: TOMATO_PRICE
A16: Tomato Labor | B16: 2.5 | C16: hours/week/bed | D16: Case instructions | E16: TOMATO_HRS_PER_BED
A17: Tomato Fertilizer | B17: 880 | C17: dollars/bed | D17: Case instructions | E17: TOMATO_FERTILIZER_PER_BED
A18: Tomato Diminishing Return | B18: 0.1 | C18: percent/bed | D18: Case instructions | E18: TOMATO_DIM_PCT
A19: Carrot Max Beds | B19: 20 | C19: beds | D19: Case instructions | E19: CARROT_MAX_BEDS
A20: Carrot Price | B20: 2094 | C20: dollars/bed | D20: Case instructions | E20: CARROT_PRICE
A21: Carrot Labor | B21: =2.5/3 -> 0.83333333 | C21: hours/week/bed | D21: Case instructions | E21: CARROT_HRS_PER_BED
A22: Carrot Fertilizer | B22: 440 | C22: dollars/bed | D22: Case instructions | E22: CARROT_FERTILIZER_PER_BED
A23: Carrot Diminishing Return | B23: 0.025 | C23: percent/bed | D23: Case instructions | E23: CARROT_DIM_PCT
A24: Mesclun Max Beds | B24: 30 | C24: beds | D24: Case instructions | E24: MESCLUN_MAX_BEDS
A25: Mesclun Price | B25: 2700 | C25: dollars/bed | D25: Case instructions | E25: MESCLUN_PRICE
A26: Mesclun Labor | B26: 1.25 | C26: hours/week/bed | D26: Case instructions | E26: MESCLUN_HRS_PER_BED
A27: Mesclun Fertilizer | B27: 880 | C27: dollars/bed | D27: Case instructions | E27: MESCLUN_FERTILIZER_PER_BED
A28: Mesclun Diminishing Return | B28: 0.0125 | C28: percent/bed | D28: Case instructions | E28: MESCLUN_DIM_PCT
A30: Blue font = hardcoded input. 0.02 acres/bed is retained as a modeling assumption; the case also limits total beds to 64.

Sheet Marginal Analysis
A1: Standalone Marginal Analysis by Crop
A2: First P≈MC crossing is the first transition from nonnegative to negative marginal profit. Later nonmonotonic behavior is retained rather than hidden.
A4: Tomato — standalone schedule | M4: Standalone check | N4: Tomato
A5: Bed q | B5: Revenue ($) | C5: Labor Hrs | D5: Farmer Hrs | E5: Temp Hrs | F5: Labor Cost ($) | G5: Fertilizer ($) | H5: Variable Cost ($) | I5: Marginal Cost ($) | J5: Marginal Profit ($) | K5: Cumulative Contribution ($) | M5: First negative MP bed | N5: =IF(J7<0,A7,IF(J8<0,A8,IF(J9<0,A9,IF(J10<0,A10,IF(J11<0,A11,IF(J12<0,A12,IF(J13<0,A13,IF(J14<0,A14,IF(J15<0,A15,IF(J16<0,A16,IF(J17<0,A17,IF(J18<0,A18,IF(J19<0,A19,IF(J20<0,A20,IF(J21<0,A21,IF(J22<0,A22,IF(J23<0,A23,IF(J24<0,A24,IF(J25<0,A25,IF(J26<0,A26,20)))))))))))))))))))) -> 11
A6: 0 | B6: =A6*Inputs!$B$15 -> 0 | C6: =A6*Inputs!$B$16*Inputs!$B$4*(1+Inputs!$B$18)^A6 -> 0 | D6: =MIN(C6,Inputs!$B$9) -> 0 | E6: =MAX(C6-Inputs!$B$9,0) -> 0 | F6: =D6*Inputs!$B$10+E6*Inputs!$B$12 -> 0 | G6: =A6*Inputs!$B$17 -> 0 | H6: =F6+G6 -> 0 | K6: =B6-H6 -> 0 | M6: Approx. P≈MC bed | N6: =N5-1 -> 10
A7: 1 | B7: =A7*Inputs!$B$15 -> 8800 | C7: =A7*Inputs!$B$16*Inputs!$B$4*(1+Inputs!$B$18)^A7 -> 99 | D7: =MIN(C7,Inputs!$B$9) -> 99 | E7: =MAX(C7-Inputs!$B$9,0) -> 0 | F7: =D7*Inputs!$B$10+E7*Inputs!$B$12 -> 3437.5 | G7: =A7*Inputs!$B$17 -> 880 | H7: =F7+G7 -> 4317.5 | I7: =H7-H6 -> 4317.5 | J7: =Inputs!$B$15-I7 -> 4482.5 | K7: =B7-H7 -> 4482.5
A8: 2 | B8: =A8*Inputs!$B$15 -> 17600 | C8: =A8*Inputs!$B$16*Inputs!$B$4*(1+Inputs!$B$18)^A8 -> 217.8 | D8: =MIN(C8,Inputs!$B$9) -> 217.8 | E8: =MAX(C8-Inputs!$B$9,0) -> 0 | F8: =D8*Inputs!$B$10+E8*Inputs!$B$12 -> 7562.5 | G8: =A8*Inputs!$B$17 -> 1760 | H8: =F8+G8 -> 9322.5 | I8: =H8-H7 -> 5005 | J8: =Inputs!$B$15-I8 -> 3795 | K8: =B8-H8 -> 8277.5
A9: 3 | B9: =A9*Inputs!$B$15 -> 26400 | C9: =A9*Inputs!$B$16*Inputs!$B$4*(1+Inputs!$B$18)^A9 -> 359.37 | D9: =MIN(C9,Inputs!$B$9) -> 359.37 | E9: =MAX(C9-Inputs!$B$9,0) -> 0 | F9: =D9*Inputs!$B$10+E9*Inputs!$B$12 -> 12478.125 | G9: =A9*Inputs!$B$17 -> 2640 | H9: =F9+G9 -> 15118.125 | I9: =H9-H8 -> 5795.625 | J9: =Inputs!$B$15-I9 -> 3004.375 | K9: =B9-H9 -> 11281.875
A10: 4 | B10: =A10*Inputs!$B$15 -> 35200 | C10: =A10*Inputs!$B$16*Inputs!$B$4*(1+Inputs!$B$18)^A10 -> 527.076 | D10: =MIN(C10,Inputs!$B$9) -> 527.076 | E10: =MAX(C10-Inputs!$B$9,0) -> 0 | F10: =D10*Inputs!$B$10+E10*Inputs!$B$12 -> 18301.25 | G10: =A10*Inputs!$B$17 -> 3520 | H10: =F10+G10 -> 21821.25 | I10: =H10-H9 -> 6703.125 | J10: =Inputs!$B$15-I10 -> 2096.875 | K10: =B10-H10 -> 13378.75
A11: 5 | B11: =A11*Inputs!$B$15 -> 44000 | C11: =A11*Inputs!$B$16*Inputs!$B$4*(1+Inputs!$B$18)^A11 -> 724.7295 | D11: =MIN(C11,Inputs!$B$9) -> 720 | E11: =MAX(C11-Inputs!$B$9,0) -> 4.7295 | F11: =D11*Inputs!$B$10+E11*Inputs!$B$12 -> 25082.109 | G11: =A11*Inputs!$B$17 -> 4400 | H11: =F11+G11 -> 29482.109 | I11: =H11-H10 -> 7660.8594 | J11: =Inputs!$B$15-I11 -> 1139.1406 | K11: =B11-H11 -> 14517.891
A12: 6 | B12: =A12*Inputs!$B$15 -> 52800 | C12: =A12*Inputs!$B$16*Inputs!$B$4*(1+Inputs!$B$18)^A12 -> 956.64294 | D12: =MIN(C12,Inputs!$B$9) -> 720 | E12: =MAX(C12-Inputs!$B$9,0) -> 236.64294 | F12: =D12*Inputs!$B$10+E12*Inputs!$B$12 -> 29108.384 | G12: =A12*Inputs!$B$17 -> 5280 | H12: =F12+G12 -> 34388.384 | I12: =H12-H11 -> 4906.275 | J12: =Inputs!$B$15-I12 -> 3893.725 | K12: =B12-H12 -> 18411.616
A13: 7 | B13: =A13*Inputs!$B$15 -> 61600 | C13: =A13*Inputs!$B$16*Inputs!$B$4*(1+Inputs!$B$18)^A13 -> 1227.6918 | D13: =MIN(C13,Inputs!$B$9) -> 720 | E13: =MAX(C13-Inputs!$B$9,0) -> 507.69177 | F13: =D13*Inputs!$B$10+E13*Inputs!$B$12 -> 33814.093 | G13: =A13*Inputs!$B$17 -> 6160 | H13: =F13+G13 -> 39974.093 | I13: =H13-H12 -> 5585.7089 | J13: =Inputs!$B$15-I13 -> 3214.2911 | K13: =B13-H13 -> 21625.907
A14: 8 | B14: =A14*Inputs!$B$15 -> 70400 | C14: =A14*Inputs!$B$16*Inputs!$B$4*(1+Inputs!$B$18)^A14 -> 1543.3839 | D14: =MIN(C14,Inputs!$B$9) -> 720 | E14: =MAX(C14-Inputs!$B$9,0) -> 823.38394 | F14: =D14*Inputs!$B$10+E14*Inputs!$B$12 -> 39294.86 | G14: =A14*Inputs!$B$17 -> 7040 | H14: =F14+G14 -> 46334.86 | I14: =H14-H13 -> 6360.7668 | J14: =Inputs!$B$15-I14 -> 2439.2332 | K14: =B14-H14 -> 24065.14
A15: 9 | B15: =A15*Inputs!$B$15 -> 79200 | C15: =A15*Inputs!$B$16*Inputs!$B$4*(1+Inputs!$B$18)^A15 -> 1909.9376 | D15: =MIN(C15,Inputs!$B$9) -> 720 | E15: =MAX(C15-Inputs!$B$9,0) -> 1189.9376 | F15: =D15*Inputs!$B$10+E15*Inputs!$B$12 -> 45658.639 | G15: =A15*Inputs!$B$17 -> 7920 | H15: =F15+G15 -> 53578.639 | I15: =H15-H14 -> 7243.7793 | J15: =Inputs!$B$15-I15 -> 1556.2207 | K15: =B15-H15 -> 25621.361
A16: 10 | B16: =A16*Inputs!$B$15 -> 88000 | C16: =A16*Inputs!$B$16*Inputs!$B$4*(1+Inputs!$B$18)^A16 -> 2334.3682 | D16: =MIN(C16,Inputs!$B$9) -> 720 | E16: =MAX(C16-Inputs!$B$9,0) -> 1614.3682 | F16: =D16*Inputs!$B$10+E16*Inputs!$B$12 -> 53027.226 | G16: =A16*Inputs!$B$17 -> 8800 | H16: =F16+G16 -> 61827.226 | I16: =H16-H15 -> 8248.5865 | J16: =Inputs!$B$15-I16 -> 551.41347 | K16: =B16-H16 -> 26172.774
A17: 11 | B17: =A17*Inputs!$B$15 -> 96800 | C17: =A17*Inputs!$B$16*Inputs!$B$4*(1+Inputs!$B$18)^A17 -> 2824.5855 | D17: =MIN(C17,Inputs!$B$9) -> 720 | E17: =MAX(C17-Inputs!$B$9,0) -> 2104.5855 | F17: =D17*Inputs!$B$10+E17*Inputs!$B$12 -> 61537.943 | G17: =A17*Inputs!$B$17 -> 9680 | H17: =F17+G17 -> 71217.943 | I17: =H17-H16 -> 9390.7174 | J17: =Inputs!$B$15-I17 -> -590.71745 | K17: =B17-H17 -> 25582.057
A18: 12 | B18: =A18*Inputs!$B$15 -> 105600 | C18: =A18*Inputs!$B$16*Inputs!$B$4*(1+Inputs!$B$18)^A18 -> 3389.5026 | D18: =MIN(C18,Inputs!$B$9) -> 720 | E18: =MAX(C18-Inputs!$B$9,0) -> 2669.5026 | F18: =D18*Inputs!$B$10+E18*Inputs!$B$12 -> 71345.532 | G18: =A18*Inputs!$B$17 -> 10560 | H18: =F18+G18 -> 81905.532 | I18: =H18-H17 -> 10687.589 | J18: =Inputs!$B$15-I18 -> -1887.5887 | K18: =B18-H18 -> 23694.468
... A26: 20 | B26: =A26*Inputs!$B$15 -> 176000 | C26: =A26*Inputs!$B$16*Inputs!$B$4*(1+Inputs!$B$18)^A26 -> 12109.5 | D26: =MIN(C26,Inputs!$B$9) -> 720 | E26: =MAX(C26-Inputs!$B$9,0) -> 11389.5 | F26: =D26*Inputs!$B$10+E26*Inputs!$B$12 -> 222734.37 | G26: =A26*Inputs!$B$17 -> 17600 | H26: =F26+G26 -> 240334.37 | I26: =H26-H25 -> 29548.324 | J26: =Inputs!$B$15-I26 -> -20748.324 | K26: =B26-H26 -> -64334.373
A29: Carrot — standalone schedule | M29: Standalone check | N29: Carrot
A30: Bed q | B30: Revenue ($) | C30: Labor Hrs | D30: Farmer Hrs | E30: Temp Hrs | F30: Labor Cost ($) | G30: Fertilizer ($) | H30: Variable Cost ($) | I30: Marginal Cost ($) | J30: Marginal Profit ($) | K30: Cumulative Contribution ($) | M30: First negative MP bed | N30: =IF(J32<0,A32,IF(J33<0,A33,IF(J34<0,A34,IF(J35<0,A35,IF(J36<0,A36,IF(J37<0,A37,IF(J38<0,A38,IF(J39<0,A39,IF(J40<0,A40,IF(J41<0,A41,IF(J42<0,A42,IF(J43<0,A43,IF(J44<0,A44,IF(J45<0,A45,IF(J46<0,A46,IF(J47<0,A47,IF(J48<0,A48,IF(J49<0,A49,IF(J50<0,A50,IF(J51<0,A51,20)))))))))))))))))))) -> 11
A31: 0 | B31: =A31*Inputs!$B$20 -> 0 | C31: =A31*Inputs!$B$21*Inputs!$B$4*(1+Inputs!$B$23)^A31 -> 0 | D31: =MIN(C31,Inputs!$B$9) -> 0 | E31: =MAX(C31-Inputs!$B$9,0) -> 0 | F31: =D31*Inputs!$B$10+E31*Inputs!$B$12 -> 0 | G31: =A31*Inputs!$B$22 -> 0 | H31: =F31+G31 -> 0 | K31: =B31-H31 -> 0 | M31: Approx. P≈MC bed | N31: =N30-1 -> 10
A32: 1 | B32: =A32*Inputs!$B$20 -> 2094 | C32: =A32*Inputs!$B$21*Inputs!$B$4*(1+Inputs!$B$23)^A32 -> 30.75 | D32: =MIN(C32,Inputs!$B$9) -> 30.75 | E32: =MAX(C32-Inputs!$B$9,0) -> 0 | F32: =D32*Inputs!$B$10+E32*Inputs!$B$12 -> 1067.7083 | G32: =A32*Inputs!$B$22 -> 440 | H32: =F32+G32 -> 1507.7083 | I32: =H32-H31 -> 1507.7083 | J32: =Inputs!$B$20-I32 -> 586.29167 | K32: =B32-H32 -> 586.29167
A33: 2 | B33: =A33*Inputs!$B$20 -> 4188 | C33: =A33*Inputs!$B$21*Inputs!$B$4*(1+Inputs!$B$23)^A33 -> 63.0375 | D33: =MIN(C33,Inputs!$B$9) -> 63.0375 | E33: =MAX(C33-Inputs!$B$9,0) -> 0 | F33: =D33*Inputs!$B$10+E33*Inputs!$B$12 -> 2188.8021 | G33: =A33*Inputs!$B$22 -> 880 | H33: =F33+G33 -> 3068.8021 | I33: =H33-H32 -> 1561.0937 | J33: =Inputs!$B$20-I33 -> 532.90625 | K33: =B33-H33 -> 1119.1979
A34: 3 | B34: =A34*Inputs!$B$20 -> 6282 | C34: =A34*Inputs!$B$21*Inputs!$B$4*(1+Inputs!$B$23)^A34 -> 96.920156 | D34: =MIN(C34,Inputs!$B$9) -> 96.920156 | E34: =MAX(C34-Inputs!$B$9,0) -> 0 | F34: =D34*Inputs!$B$10+E34*Inputs!$B$12 -> 3365.2832 | G34: =A34*Inputs!$B$22 -> 1320 | H34: =F34+G34 -> 4685.2832 | I34: =H34-H33 -> 1616.4811 | J34: =Inputs!$B$20-I34 -> 477.51888 | K34: =B34-H34 -> 1596.7168
A35: 4 | B35: =A35*Inputs!$B$20 -> 8376 | C35: =A35*Inputs!$B$21*Inputs!$B$4*(1+Inputs!$B$23)^A35 -> 132.45755 | D35: =MIN(C35,Inputs!$B$9) -> 132.45755 | E35: =MAX(C35-Inputs!$B$9,0) -> 0 | F35: =D35*Inputs!$B$10+E35*Inputs!$B$12 -> 4599.2204 | G35: =A35*Inputs!$B$22 -> 1760 | H35: =F35+G35 -> 6359.2204 | I35: =H35-H34 -> 1673.9372 | J35: =Inputs!$B$20-I35 -> 420.06283 | K35: =B35-H35 -> 2016.7796
A36: 5 | B36: =A36*Inputs!$B$20 -> 10470 | C36: =A36*Inputs!$B$21*Inputs!$B$4*(1+Inputs!$B$23)^A36 -> 169.71123 | D36: =MIN(C36,Inputs!$B$9) -> 169.71123 | E36: =MAX(C36-Inputs!$B$9,0) -> 0 | F36: =D36*Inputs!$B$10+E36*Inputs!$B$12 -> 5892.7511 | G36: =A36*Inputs!$B$22 -> 2200 | H36: =F36+G36 -> 8092.7511 | I36: =H36-H35 -> 1733.5307 | J36: =Inputs!$B$20-I36 -> 360.46927 | K36: =B36-H36 -> 2377.2489
A37: 6 | B37: =A37*Inputs!$B$20 -> 12564 | C37: =A37*Inputs!$B$21*Inputs!$B$4*(1+Inputs!$B$23)^A37 -> 208.74482 | D37: =MIN(C37,Inputs!$B$9) -> 208.74482 | E37: =MAX(C37-Inputs!$B$9,0) -> 0 | F37: =D37*Inputs!$B$10+E37*Inputs!$B$12 -> 7248.0839 | G37: =A37*Inputs!$B$22 -> 2640 | H37: =F37+G37 -> 9888.0839 | I37: =H37-H36 -> 1795.3328 | J37: =Inputs!$B$20-I37 -> 298.66724 | K37: =B37-H37 -> 2675.9161
A38: 7 | B38: =A38*Inputs!$B$20 -> 14658 | C38: =A38*Inputs!$B$21*Inputs!$B$4*(1+Inputs!$B$23)^A38 -> 249.62401 | D38: =MIN(C38,Inputs!$B$9) -> 249.62401 | E38: =MAX(C38-Inputs!$B$9,0) -> 0 | F38: =D38*Inputs!$B$10+E38*Inputs!$B$12 -> 8667.5003 | G38: =A38*Inputs!$B$22 -> 3080 | H38: =F38+G38 -> 11747.5 | I38: =H38-H37 -> 1859.4164 | J38: =Inputs!$B$20-I38 -> 234.58358 | K38: =B38-H38 -> 2910.4997
A39: 8 | B39: =A39*Inputs!$B$20 -> 16752 | C39: =A39*Inputs!$B$21*Inputs!$B$4*(1+Inputs!$B$23)^A39 -> 292.4167 | D39: =MIN(C39,Inputs!$B$9) -> 292.4167 | E39: =MAX(C39-Inputs!$B$9,0) -> 0 | F39: =D39*Inputs!$B$10+E39*Inputs!$B$12 -> 10153.357 | G39: =A39*Inputs!$B$22 -> 3520 | H39: =F39+G39 -> 13673.357 | I39: =H39-H38 -> 1925.8572 | J39: =Inputs!$B$20-I39 -> 168.14281 | K39: =B39-H39 -> 3078.6425
A40: 9 | B40: =A40*Inputs!$B$20 -> 18846 | C40: =A40*Inputs!$B$21*Inputs!$B$4*(1+Inputs!$B$23)^A40 -> 337.193 | D40: =MIN(C40,Inputs!$B$9) -> 337.193 | E40: =MAX(C40-Inputs!$B$9,0) -> 0 | F40: =D40*Inputs!$B$10+E40*Inputs!$B$12 -> 11708.09 | G40: =A40*Inputs!$B$22 -> 3960 | H40: =F40+G40 -> 15668.09 | I40: =H40-H39 -> 1994.7329 | J40: =Inputs!$B$20-I40 -> 99.267136 | K40: =B40-H40 -> 3177.9097
A41: 10 | B41: =A41*Inputs!$B$20 -> 20940 | C41: =A41*Inputs!$B$21*Inputs!$B$4*(1+Inputs!$B$23)^A41 -> 384.02536 | D41: =MIN(C41,Inputs!$B$9) -> 384.02536 | E41: =MAX(C41-Inputs!$B$9,0) -> 0 | F41: =D41*Inputs!$B$10+E41*Inputs!$B$12 -> 13334.214 | G41: =A41*Inputs!$B$22 -> 4400 | H41: =F41+G41 -> 17734.214 | I41: =H41-H40 -> 2066.1237 | J41: =Inputs!$B$20-I41 -> 27.876341 | K41: =B41-H41 -> 3205.786
A42: 11 | B42: =A42*Inputs!$B$20 -> 23034 | C42: =A42*Inputs!$B$21*Inputs!$B$4*(1+Inputs!$B$23)^A42 -> 432.9886 | D42: =MIN(C42,Inputs!$B$9) -> 432.9886 | E42: =MAX(C42-Inputs!$B$9,0) -> 0 | F42: =D42*Inputs!$B$10+E42*Inputs!$B$12 -> 15034.326 | G42: =A42*Inputs!$B$22 -> 4840 | H42: =F42+G42 -> 19874.326 | I42: =H42-H41 -> 2140.1123 | J42: =Inputs!$B$20-I42 -> -46.112285 | K42: =B42-H42 -> 3159.6737
A43: 12 | B43: =A43*Inputs!$B$20 -> 25128 | C43: =A43*Inputs!$B$21*Inputs!$B$4*(1+Inputs!$B$23)^A43 -> 484.15998 | D43: =MIN(C43,Inputs!$B$9) -> 484.15998 | E43: =MAX(C43-Inputs!$B$9,0) -> 0 | F43: =D43*Inputs!$B$10+E43*Inputs!$B$12 -> 16811.11 | G43: =A43*Inputs!$B$22 -> 5280 | H43: =F43+G43 -> 22091.11 | I43: =H43-H42 -> 2216.784 | J43: =Inputs!$B$20-I43 -> -122.78402 | K43: =B43-H43 -> 3036.8897
... A51: 20 | B51: =A51*Inputs!$B$20 -> 41880 | C51: =A51*Inputs!$B$21*Inputs!$B$4*(1+Inputs!$B$23)^A51 -> 983.16986 | D51: =MIN(C51,Inputs!$B$9) -> 720 | E51: =MAX(C51-Inputs!$B$9,0) -> 263.16986 | F51: =D51*Inputs!$B$10+E51*Inputs!$B$12 -> 29568.921 | G51: =A51*Inputs!$B$22 -> 8800 | H51: =F51+G51 -> 38368.921 | I51: =H51-H50 -> 1688.9455 | J51: =Inputs!$B$20-I51 -> 405.05454 | K51: =B51-H51 -> 3511.0787
A54: Mesclun — standalone schedule | M54: Standalone check | N54: Mesclun
A55: Bed q | B55: Revenue ($) | C55: Labor Hrs | D55: Farmer Hrs | E55: Temp Hrs | F55: Labor Cost ($) | G55: Fertilizer ($) | H55: Variable Cost ($) | I55: Marginal Cost ($) | J55: Marginal Profit ($) | K55: Cumulative Contribution ($) | M55: First negative MP bed | N55: =IF(J57<0,A57,IF(J58<0,A58,IF(J59<0,A59,IF(J60<0,A60,IF(J61<0,A61,IF(J62<0,A62,IF(J63<0,A63,IF(J64<0,A64,IF(J65<0,A65,IF(J66<0,A66,IF(J67<0,A67,IF(J68<0,A68,IF(J69<0,A69,IF(J70<0,A70,IF(J71<0,A71,IF(J72<0,A72,IF(J73<0,A73,IF(J74<0,A74,IF(J75<0,A75,IF(J76<0,A76,IF(J77<0,A77,IF(J78<0,A78,IF(J79<0,A79,IF(J80<0,A80,IF(J81<0,A81,IF(J82<0,A82,IF(J83<0,A83,IF(J84<0,A84,IF(J85<0,A85,IF(J86<0,A86,30)))))))))))))))))))))))))))))) -> 7
A56: 0 | B56: =A56*Inputs!$B$25 -> 0 | C56: =A56*Inputs!$B$26*Inputs!$B$4*(1+Inputs!$B$28)^A56 -> 0 | D56: =MIN(C56,Inputs!$B$9) -> 0 | E56: =MAX(C56-Inputs!$B$9,0) -> 0 | F56: =D56*Inputs!$B$10+E56*Inputs!$B$12 -> 0 | G56: =A56*Inputs!$B$27 -> 0 | H56: =F56+G56 -> 0 | K56: =B56-H56 -> 0 | M56: Approx. P≈MC bed | N56: =N55-1 -> 6
A57: 1 | B57: =A57*Inputs!$B$25 -> 2700 | C57: =A57*Inputs!$B$26*Inputs!$B$4*(1+Inputs!$B$28)^A57 -> 45.5625 | D57: =MIN(C57,Inputs!$B$9) -> 45.5625 | E57: =MAX(C57-Inputs!$B$9,0) -> 0 | F57: =D57*Inputs!$B$10+E57*Inputs!$B$12 -> 1582.0312 | G57: =A57*Inputs!$B$27 -> 880 | H57: =F57+G57 -> 2462.0312 | I57: =H57-H56 -> 2462.0312 | J57: =Inputs!$B$25-I57 -> 237.96875 | K57: =B57-H57 -> 237.96875
A58: 2 | B58: =A58*Inputs!$B$25 -> 5400 | C58: =A58*Inputs!$B$26*Inputs!$B$4*(1+Inputs!$B$28)^A58 -> 92.264062 | D58: =MIN(C58,Inputs!$B$9) -> 92.264062 | E58: =MAX(C58-Inputs!$B$9,0) -> 0 | F58: =D58*Inputs!$B$10+E58*Inputs!$B$12 -> 3203.6133 | G58: =A58*Inputs!$B$27 -> 1760 | H58: =F58+G58 -> 4963.6133 | I58: =H58-H57 -> 2501.582 | J58: =Inputs!$B$25-I58 -> 198.41797 | K58: =B58-H58 -> 436.38672
A59: 3 | B59: =A59*Inputs!$B$25 -> 8100 | C59: =A59*Inputs!$B$26*Inputs!$B$4*(1+Inputs!$B$28)^A59 -> 140.12604 | D59: =MIN(C59,Inputs!$B$9) -> 140.12604 | E59: =MAX(C59-Inputs!$B$9,0) -> 0 | F59: =D59*Inputs!$B$10+E59*Inputs!$B$12 -> 4865.4877 | G59: =A59*Inputs!$B$27 -> 2640 | H59: =F59+G59 -> 7505.4877 | I59: =H59-H58 -> 2541.8744 | J59: =Inputs!$B$25-I59 -> 158.12561 | K59: =B59-H59 -> 594.51233
...

Sheet Farm Model
A1: Farm Model — Combined Crop Mix
A2: The three crop-bed decisions come from Solver. Labor is pooled farm-wide and crop labor cost is allocated at the blended farm-wide rate.
A4: Metric | B4: Tomato | C4: Carrot | D4: Mesclun | E4: Total | F4: Unit
A5: Beds | B5: =Solver!$B$5 -> 10 | C5: =Solver!$B$6 -> 20 | D5: =Solver!$B$7 -> 30 | E5: =SUM(B5:D5) -> 60 | F5: beds
A6: Labor hours | B6: =Solver!$B$5*Inputs!$B$16*Inputs!$B$4*(1+Inputs!$B$18)^Solver!$B$5 -> 2334.3682 | C6: =Solver!$B$6*Inputs!$B$21*Inputs!$B$4*(1+Inputs!$B$23)^Solver!$B$6 -> 983.16986 | D6: =Solver!$B$7*Inputs!$B$26*Inputs!$B$4*(1+Inputs!$B$28)^Solver!$B$7 -> 1959.678 | E6: =SUM(B6:D6) -> 5277.2161 | F6: hours
A7: Revenue | B7: =Solver!$B$5*Inputs!$B$15 -> 88000 | C7: =Solver!$B$6*Inputs!$B$20 -> 41880 | D7: =Solver!$B$7*Inputs!$B$25 -> 81000 | E7: =SUM(B7:D7) -> 210880 | F7: $
A8: Fertilizer cost | B8: =Solver!$B$5*Inputs!$B$17 -> 8800 | C8: =Solver!$B$6*Inputs!$B$22 -> 8800 | D8: =Solver!$B$7*Inputs!$B$27 -> 26400 | E8: =SUM(B8:D8) -> 44000 | F8: $
A9: Allocated labor cost | B9: =B6*'Farm Model'!$B$19 -> 46056.581 | C9: =C6*'Farm Model'!$B$19 -> 19397.729 | D9: =D6*'Farm Model'!$B$19 -> 38664.025 | E9: =SUM(B9:D9) -> 104118.34 | F9: $
A10: Variable cost | B10: =B8+B9 -> 54856.581 | C10: =C8+C9 -> 28197.729 | D10: =D8+D9 -> 65064.025 | E10: =SUM(B10:D10) -> 148118.34 | F10: $
A11: Contribution | B11: =B7-B10 -> 33143.419 | C11: =C7-C10 -> 13682.271 | D11: =D7-D10 -> 15935.975 | E11: =SUM(B11:D11) -> 62761.665 | F11: $
A14: Farm-wide Labor and Profit
A15: Farmer hours used | B15: =MIN('Farm Model'!$E$6,Inputs!$B$9) -> 720 | C15: hours
A16: Temporary labor hours | B16: =MAX('Farm Model'!$E$6-Inputs!$B$9,0) -> 4557.2161 | C16: hours
A17: Temporary workers required | B17: =IF(B16=0,0,B16/Inputs!$B$11) -> 3.1647334 | C17: workers
A18: Total labor cost | B18: =B15*Inputs!$B$10+B16*Inputs!$B$12 -> 104118.34 | C18: $
A19: Blended labor rate | B19: =IF('Farm Model'!$E$6=0,0,B18/'Farm Model'!$E$6) -> 19.729784 | C19: $/hour
A20: Total variable cost | B20: =B18+'Farm Model'!$E$8 -> 148118.34 | C20: $
A21: Fixed cost | B21: =Inputs!$B$8 -> 20000 | C21: $
A22: Total cost | B22: =B20+B21 -> 168118.34 | C22: $
A23: Season profit | B23: ='Farm Model'!$E$7-B22 -> 42761.665 | C23: $
A24: Land used | B24: ='Farm Model'!$E$5*Inputs!$B$6 -> 1.2 | C24: acres

Sheet Solver
A1: Solver Setup — Optimize Season Profit
A2: Excel Solver settings: Objective = Season Profit (Max); Changing Cells = B5:B7; GRG Nonlinear; add B5:B7 = integer. Start with 0/0/0 for the first audit run.
A4: Decision variable | B4: Starting value | C4: Contract name
A5: Tomato beds | B5: 10 | C5: TOMATO_BEDS
A6: Carrot beds | B6: 20 | C6: CARROT_BEDS
A7: Mesclun beds | B7: 30 | C7: MESCLUN_BEDS
A9: Objective | B9: Value
A10: Season Profit | B10: ='Farm Model'!$B$23 -> 42761.665
A12: Constraint | B12: LHS | C12: Relation | D12: RHS | E12: Status
A13: Tomato max | B13: =Solver!$B$5 -> 10 | C13: <= | D13: =Inputs!$B$14 -> 20 | E13: =IF(B13>D13+0.000001,"VIOLATED",IF(ABS(B13-D13)<0.000001,"BINDING","SLACK")) -> SLACK
A14: Carrot max | B14: =Solver!$B$6 -> 20 | C14: <= | D14: =Inputs!$B$19 -> 20 | E14: =IF(B14>D14+0.000001,"VIOLATED",IF(ABS(B14-D14)<0.000001,"BINDING","SLACK")) -> BINDING
A15: Mesclun max | B15: =Solver!$B$7 -> 30 | C15: <= | D15: =Inputs!$B$24 -> 30 | E15: =IF(B15>D15+0.000001,"VIOLATED",IF(ABS(B15-D15)<0.000001,"BINDING","SLACK")) -> BINDING
A16: Total beds | B16: ='Farm Model'!$E$5 -> 60 | C16: <= | D16: =Inputs!$B$7 -> 64 | E16: =IF(B16>D16+0.000001,"VIOLATED",IF(ABS(B16-D16)<0.000001,"BINDING","SLACK")) -> SLACK
A17: Temp workers | B17: ='Farm Model'!$B$17 -> 3.1647334 | C17: <= | D17: =Inputs!$B$13 -> 4 | E17: =IF(B17>D17+0.000001,"VIOLATED",IF(ABS(B17-D17)<0.000001,"BINDING","SLACK")) -> SLACK
A18: Land used | B18: ='Farm Model'!$B$24 -> 1.2 | C18: <= | D18: =Inputs!$B$5 -> 1.5 | E18: =IF(B18>D18+0.000001,"VIOLATED",IF(ABS(B18-D18)<0.000001,"BINDING","SLACK")) -> SLACK
A21: Additional-Bed Diagnostics (farm-wide)
A22: Crop | B22: Profit if +1 bed | C22: Incremental profit | D22: Cap/space check | E22: Decision flag | F22: Note
A23: Tomato | B23: =(((Solver!$B$5+1))*Inputs!$B$15+(Solver!$B$6)*Inputs!$B$20+(Solver!$B$7)*Inputs!$B$25)-(MIN((((Solver!$B$5+1))*Inputs!$B$16*Inputs!$B$4*(1+Inputs!$B$18)^((Solver!$B$5+1))+(Solver!$B$6)*Inputs!$B$21*Inputs!$B$4*(1+Inputs!$B$23)^(Solver!$B$6)+(Solver!$B$7)*Inputs!$B$26*Inputs!$B$4*(1+Inputs!$B$28)^(Solver!$B$7)),Inputs!$B$9)*Inputs!$B$10+MAX((((Solver!$B$5+1))*Inputs!$B$16*Inputs!$B$4*(1+Inputs!$B$18)^((Solver!$B$5+1))+(Solver!$B$6)*Inputs!$B$21*Inputs!$B$4*(1+Inputs!$B$23)^(Solver!$B$6)+(Solver!$B$7)*Inputs!$B$26*Inputs!$B$4*(1+Inputs!$B$28)^(Solver!$B$7))-Inputs!$B$9,0)*Inputs!$B$12)-(((Solver!$B$5+1))*Inputs!$B$17+(Solver!$B$6)*Inputs!$B$22+(Solver!$B$7)*Inputs!$B$27)-Inputs!$B$8 -> 42170.947 | C23: =B23-'Farm Model'!$B$23 -> -590.71745 | D23: =IF(AND(Solver!$B$5<Inputs!$B$14,'Farm Model'!$E$5<Inputs!$B$7,'Farm Model'!$B$24+Inputs!$B$6<=Inputs!$B$5),"SPACE AVAILABLE","CONSTRAINT BLOCKS") -> SPACE AVAILABLE | E23: =IF(D23="CONSTRAINT BLOCKS","PREVENTED BY CONSTRAINT",IF(C23>0,"PROFITABLE","NOT PROFITABLE")) -> NOT PROFITABLE | F23: Evaluated against current crop mix
A24: Carrot | B24: =((Solver!$B$5)*Inputs!$B$15+((Solver!$B$6+1))*Inputs!$B$20+(Solver!$B$7)*Inputs!$B$25)-(MIN(((Solver!$B$5)*Inputs!$B$16*Inputs!$B$4*(1+Inputs!$B$18)^(Solver!$B$5)+((Solver!$B$6+1))*Inputs!$B$21*Inputs!$B$4*(1+Inputs!$B$23)^((Solver!$B$6+1))+(Solver!$B$7)*Inputs!$B$26*Inputs!$B$4*(1+Inputs!$B$28)^(Solver!$B$7)),Inputs!$B$9)*Inputs!$B$10+MAX(((Solver!$B$5)*Inputs!$B$16*Inputs!$B$4*(1+Inputs!$B$18)^(Solver!$B$5)+((Solver!$B$6+1))*Inputs!$B$21*Inputs!$B$4*(1+Inputs!$B$23)^((Solver!$B$6+1))+(Solver!$B$7)*Inputs!$B$26*Inputs!$B$4*(1+Inputs!$B$28)^(Solver!$B$7))-Inputs!$B$9,0)*Inputs!$B$12)-((Solver!$B$5)*Inputs!$B$17+((Solver!$B$6+1))*Inputs!$B$22+(Solver!$B$7)*Inputs!$B$27)-Inputs!$B$8 -> 43114.159 | C24: =B24-'Farm Model'!$B$23 -> 352.49475 | D24: =IF(AND(Solver!$B$6<Inputs!$B$19,'Farm Model'!$E$5<Inputs!$B$7,'Farm Model'!$B$24+Inputs!$B$6<=Inputs!$B$5),"SPACE AVAILABLE","CONSTRAINT BLOCKS") -> CONSTRAINT BLOCKS | E24: =IF(D24="CONSTRAINT BLOCKS","PREVENTED BY CONSTRAINT",IF(C24>0,"PROFITABLE","NOT PROFITABLE")) -> PREVENTED BY CONSTRAINT | F24: Evaluated against current crop mix
A25: Mesclun | B25: =((Solver!$B$5)*Inputs!$B$15+(Solver!$B$6)*Inputs!$B$20+((Solver!$B$7+1))*Inputs!$B$25)-(MIN(((Solver!$B$5)*Inputs!$B$16*Inputs!$B$4*(1+Inputs!$B$18)^(Solver!$B$5)+(Solver!$B$6)*Inputs!$B$21*Inputs!$B$4*(1+Inputs!$B$23)^(Solver!$B$6)+((Solver!$B$7+1))*Inputs!$B$26*Inputs!$B$4*(1+Inputs!$B$28)^((Solver!$B$7+1))),Inputs!$B$9)*Inputs!$B$10+MAX(((Solver!$B$5)*Inputs!$B$16*Inputs!$B$4*(1+Inputs!$B$18)^(Solver!$B$5)+(Solver!$B$6)*Inputs!$B$21*Inputs!$B$4*(1+Inputs!$B$23)^(Solver!$B$6)+((Solver!$B$7+1))*Inputs!$B$26*Inputs!$B$4*(1+Inputs!$B$28)^((Solver!$B$7+1)))-Inputs!$B$9,0)*Inputs!$B$12)-((Solver!$B$5)*Inputs!$B$17+(Solver!$B$6)*Inputs!$B$22+((Solver!$B$7+1))*Inputs!$B$27)-Inputs!$B$8 -> 43008.138 | C25: =B25-'Farm Model'!$B$23 -> 246.4738 | D25: =IF(AND(Solver!$B$7<Inputs!$B$24,'Farm Model'!$E$5<Inputs!$B$7,'Farm Model'!$B$24+Inputs!$B$6<=Inputs!$B$5),"SPACE AVAILABLE","CONSTRAINT BLOCKS") -> CONSTRAINT BLOCKS | E25: =IF(D25="CONSTRAINT BLOCKS","PREVENTED BY CONSTRAINT",IF(C25>0,"PROFITABLE","NOT PROFITABLE")) -> PREVENTED BY CONSTRAINT | F25: Evaluated against current crop mix
A27: The workbook intentionally opens at 0/0/0. Run Solver to generate the optimized mix; published results are validation targets, not hardcoded decision values.

Sheet Audit
A1: Audit — Validation Checks
A2: Solver starting-point tests and the Farm Profit Lab cross-check are intentionally left for the student's post-build audit.
A4: Check | B4: Expected | C4: Workbook result / entry | D4: Status | E4: Student finding | F4: Action if failed
A5: Tomato q=1 labor hours | B5: 99 | C5: ='Marginal Analysis'!C7 -> 99 | D5: =IF(ABS(C5-B5)<0.000001,"PASS","FAIL") -> PASS | F5: Fix spec/model if not 99
A6: Published optimal mix | B6: 10 / 20 / 30 | C6: =Solver!$B$5&" / "&Solver!$B$6&" / "&Solver!$B$7 -> 10 / 20 / 30 | D6: =IF(C6=B6,"PASS","CHECK") -> PASS | F6: Run Solver; investigate if different
A7: Published season profit | B7: 42762 | C7: ='Farm Model'!$B$23 -> 42761.665 | D7: =IF(ABS(C7-B7)<=50,"PASS","CHECK") -> PASS | E7: Ths is similar to the marginal analysis comparison. The lab reports rounded whole dollar results while our model keeps more precise input values which explains the small diffrence in seasonal profit. | F7: Investigate meaningful difference
A8: Standalone P≈MC — Tomato | B8: 10 | C8: ='Marginal Analysis'!$N$6 -> 10 | D8: =IF(C8=B8,"PASS","CHECK") -> PASS | F8: Check first negative MP crossing
A9: Standalone P≈MC — Carrot | B9: 10 | C9: ='Marginal Analysis'!$N$31 -> 10 | D9: =IF(C9=B9,"PASS","CHECK") -> PASS | F9: Check first negative MP crossing
A10: Standalone P≈MC — Mesclun | B10: 6 | C10: ='Marginal Analysis'!$N$56 -> 6 | D10: =IF(C10=B10,"PASS","CHECK") -> PASS | F10: Check first negative MP crossing
A11: Solver start 0/0/0 | B11: Run and record | C11: 10 / 20 / 30 | D11: PASS | F11: Record solution
A12: Solver start 20/0/0 | B12: Run and record | C12: 10 / 20 / 30 | D12: PASS | F12: Record solution
A13: Intermediate MC vs Farm Profit Lab | B13: Compare one bed | C13: Tomatobed10:MP$551.41 vs Lab $551 | D13: PASS | E13: The farm lab is displaying a whole dollar result but our model is more granular . It is uses the actual components to make the calculations that can be audited | F13: Record comparison
A14: Tomato MC dip around bed 6 | B14: Observe dip | C14: ='Marginal Analysis'!I12 -> 4906.275 | D14: OBSERVE | E14: More temp labor is used after the farmer reaches the 720 hours limit. Temp labor has a lower hourly rate so marginal labor cost falls even though total labor hours increase | F14: Do not treat dip as formula error
A15: No Excel formula erros | B15: No error cells | C15: No error cells were found | D15: PASS | E15: Excel found no formula error cells which indicates that formulas noted in spec worked in model rather than producing error values
A16: Calculated cells cotain formulas | B16: Formulas notpasted values | C16: Formulas verified | D16: PASS | E16: The farm model results were based on calculations that can be audited and verified
